<?xml version="1.0"?>
<!-- This URDF was automatically created by SolidWorks to URDF Exporter! Originally created by Stephen Brawner (brawner@gmail.com) 
     Commit Version: 1.6.0-4-g7f85cfe  Build Version: 1.6.7995.38578
     For more information, please see http://wiki.ros.org/sw_urdf_exporter -->

 <robot name="autobot" xmlns:xacro="http://www.ros.org/wiki/xacro">

 <xacro:include filename="$(find autobot_description)/urdf/autobot.gazebo" /> 
  
<link name="base_footprint" />
  <link
    name="base_link">
    <inertial>
      <origin
        xyz="-0.00675741967955223 -3.94368233620065E-19 0.144685974224454"
        rpy="0 0 0" />
      <mass
        value="50.0737764393225" />
      <inertia
        ixx="1.60243962514024"
        ixy="-3.58259015894589E-17"
        ixz="-7.32857171828121E-05"
        iyy="3.76342947196976"
        iyz="-1.01570985550491E-17"
        izz="4.2275358136604" />
    </inertial>
    <visual>
      <origin
        xyz="0 0 0"
        rpy="0 0 0" />
      <geometry>
        <mesh
          filename="package://autobot_description/meshes/base_link.STL" />
      </geometry>
      <material
        name="">
        <color
          rgba="0.792156862745098 0.819607843137255 0.933333333333333 1" />
      </material>
    </visual>
    <collision>
      <origin
        xyz="0 0 0"
        rpy="0 0 0" />
      <geometry>
        <mesh
          filename="package://autobot_description/meshes/base_link.STL" />
      </geometry>
    </collision>
  </link>

  <joint name="base_joint" type="fixed" >
          <parent link="base_footprint" />
          <child link="base_link" />
  </joint>


  <link
    name="lw_Link">
    <inertial>
      <origin
        xyz="6.90369340232412E-17 -0.0233656076415494 1.38777878078145E-17"
        rpy="0 0 0" />
      <mass
        value="0.894897654342253" />
      <inertia
        ixx="0.00154662662430532"
        ixy="-1.22284382050737E-18"
        ixz="6.1245768287588E-15"
        iyy="0.00273077093357436"
        iyz="-1.04148499974777E-18"
        izz="0.00154662662430532" />
    </inertial>
    <visual>
      <origin
        xyz="0 0 0"
        rpy="0 0 0" />
      <geometry>
        <mesh
          filename="package://autobot_description/meshes/lw_Link.STL" />
      </geometry>
      <material
        name="">
        <color
          rgba="0.752941176470588 0.752941176470588 0.752941176470588 1" />
      </material>
    </visual>
    <collision>
      <origin
        xyz="0 0 0"
        rpy="0 0 0" />
      <geometry>
        <mesh
          filename="package://autobot_description/meshes/lw_Link.STL" />
      </geometry>
    </collision>
  </link>
  <joint
    name="lwj"
    type="continuous">
    <origin
      xyz="0.0021014 0.26 0.02"
      rpy="0 0 0" />
    <parent
      link="base_link" />
    <child
      link="lw_Link" />
    <axis
      xyz="0 1 0" />
  </joint>
  <link
    name="rw_Link">
    <inertial>
      <origin
        xyz="-1.57558981881761E-16 0.023369306249288 -1.38777878078145E-16"
        rpy="0 0 0" />
      <mass
        value="0.894691008404633" />
      <inertia
        ixx="0.0015462308660348"
        ixy="-1.20837780260624E-18"
        ixz="-4.88349597569349E-15"
        iyy="0.00273004368325259"
        iyz="-2.46296988767188E-18"
        izz="0.00154623086602977" />
    </inertial>
    <visual>
      <origin
        xyz="0 0 0"
        rpy="0 0 0" />
      <geometry>
        <mesh
          filename="package://autobot_description/meshes/rw_Link.STL" />
      </geometry>
      <material
        name="">
        <color
          rgba="0.752941176470588 0.752941176470588 0.752941176470588 1" />
      </material>
    </visual>
    <collision>
      <origin
        xyz="0 0 0"
        rpy="0 0 0" />
      <geometry>
        <mesh
          filename="package://autobot_description/meshes/rw_Link.STL" />
      </geometry>
    </collision>
  </link>
  <joint
    name="rwj"
    type="continuous">
    <origin
      xyz="0.0021014 -0.26 0.02"
      rpy="0 0 0" />
    <parent
      link="base_link" />
    <child
      link="rw_Link" />
    <axis
      xyz="0 1 0" />
  </joint>
  <link
    name="sfw_Link">
    <inertial>
      <origin
        xyz="-5.55111512312578E-17 -2.7829305649018E-19 0"
        rpy="0 0 0" />
      <mass
        value="0.00858024664605096" />
      <inertia
        ixx="5.53563192616624E-07"
        ixy="-9.35489930977411E-24"
        ixz="-3.25972587038862E-23"
        iyy="5.53563192616624E-07"
        iyz="-3.64090187410903E-24"
        izz="5.53563192616624E-07" />
    </inertial>
    <visual>
      <origin
        xyz="0 0 0"
        rpy="0 0 0" />
      <geometry>
        <mesh
          filename="package://autobot_description/meshes/sfw_Link.STL" />
      </geometry>
      <material
        name="">
        <color
          rgba="0.792156862745098 0.819607843137255 0.933333333333333 1" />
      </material>
    </visual>
    <collision>
      <origin
        xyz="0 0 0"
        rpy="0 0 0" />
      <geometry>
        <mesh
          filename="package://autobot_description/meshes/sfw_Link.STL" />
      </geometry>
    </collision>
  </link>
  <joint
    name="sfj"
    type="continuous">
    <origin
      xyz="0.2821 0 -0.047293"
      rpy="0 0 0" />
    <parent
      link="base_link" />
    <child
      link="sfw_Link" />
    <axis
      xyz="1 0 0" />
  </joint>
  <link
    name="sbw_Link">
    <inertial>
      <origin
        xyz="0 -2.7829305649018E-19 0"
        rpy="0 0 0" />
      <mass
        value="0.00858024664605096" />
      <inertia
        ixx="5.53563192616624E-07"
        ixy="-9.35489930977411E-24"
        ixz="-3.25972587038862E-23"
        iyy="5.53563192616624E-07"
        iyz="-3.64090187410903E-24"
        izz="5.53563192616624E-07" />
    </inertial>
    <visual>
      <origin
        xyz="0 0 0"
        rpy="0 0 0" />
      <geometry>
        <mesh
          filename="package://autobot_description/meshes/sfw_Link.STL" />
      </geometry>
      <material
        name="">
        <color
          rgba="0.792156862745098 0.819607843137255 0.933333333333333 1" />
      </material>
    </visual>
    <collision>
      <origin
        xyz="0 0 0"
        rpy="0 0 0" />
      <geometry>
        <mesh
          filename="package://autobot_description/meshes/sfw_Link.STL" />
      </geometry>
    </collision>
  </link>
  <joint
    name="sbj"
    type="continuous">
    <origin
      xyz="-0.2779 0 -0.047293"
      rpy="0 0 0" />
    <parent
      link="base_link" />
    <child
      link="sbw_Link" />
    <axis
      xyz="1 0 0" />
  </joint>
  <link
    name="laser">
    <inertial>
      <origin
        xyz="0 0 0"
        rpy="0 0 0" />
      <mass
        value="0.307718535381243" />
      <inertia
        ixx="0.00022876790983422"
        ixy="-2.33653051131992E-36"
        ixz="4.87218547817546E-21"
        iyy="0.00022876790983422"
        iyz="-7.3468396926393E-37"
        izz="0.000377936744279225" />
    </inertial>
    <visual>
      <origin
        xyz="0 0 0"
        rpy="0 0 0" />
      <geometry>
        <mesh
          filename="package://autobot_description/meshes/laser.STL" />
      </geometry>
      <material
        name="">
        <color
          rgba="0.792156862745098 0.819607843137255 0.933333333333333 1" />
      </material>
    </visual>
    <collision>
      <origin
        xyz="0 0 0"
        rpy="0 0 0" />
      <geometry>
        <mesh
          filename="package://autobot_description/meshes/laser.STL" />
      </geometry>
    </collision>
  </link>
  <joint
    name="laser_j"
    type="fixed">
    <origin
      xyz="0.18 0.21 0.40"
      rpy="0 0 0" />
    <parent
      link="base_link" />
    <child
      link="laser" />
    <axis
      xyz="0 0 0" />
  </joint>
  <link
    name="camera_link">
    <inertial>
      <origin
        xyz="-0.0125485107775065 -0.0022932914401362 -6.05650127629239E-05"
        rpy="0 0 0" />
      <mass
        value="0.044752252792694" />
      <inertia
        ixx="2.7277562304993E-05"
        ixy="2.44344702271009E-07"
        ixz="-1.17331447377196E-09"
        iyy="3.94472748626512E-06"
        iyz="-2.80246711459393E-09"
        izz="2.73621254921554E-05" />
    </inertial>
    <visual>
      <origin
        xyz="0 0 0"
        rpy="0 0 0" />
      <geometry>
        <mesh
          filename="package://autobot_description/meshes/camera_Link.STL" />
      </geometry>
      <material
        name="">
        <color
          rgba="0.792156862745098 0.819607843137255 0.933333333333333 1" />
      </material>
    </visual>
    <collision>
      <origin
        xyz="0 0 0"
        rpy="0 0 0" />
      <geometry>
        <mesh
          filename="package://autobot_description/meshes/camera_Link.STL" />
      </geometry>
    </collision>
  </link>
  <joint
    name="camera_j"
    type="fixed">
    <origin
      xyz="0.3366 0.0025395 0.145"
      rpy="0 0 0" />
    <parent
      link="base_link" />
    <child
      link="camera_link" />
    <axis
      xyz="0 0 0" />
  </joint>

<!-- IMU -->
  <link name="imu_link">
    <collision>
      <origin xyz="0 0 0" rpy="0 0 0"/>
      <geometry>
        <mesh filename="package://autobot_description/meshes/imu.STL" />
      </geometry>
    </collision>

    <visual>
      <origin xyz="0 0 0" rpy="0 0 0"/>
    <geometry>
      <mesh filename="package://autobot_description/meshes/imu.STL" />
      </geometry>
    </visual>

    <inertial>
      <mass value="1e-5" />
      <origin xyz="0 0 0" rpy="0 0 0"/>
      <inertia ixx="0" ixy="0" ixz="0" iyy="0" iyz="0" izz="0" />
    </inertial>
  </link>

  <joint
    name="imujoint"
    type="fixed">
    <origin
      xyz="0.132 0.26 0.36"
      rpy="0 0 0" />
    <parent
      link="base_link" />
    <child
      link="imu_link" />
    <axis
      xyz="0 0 0" />
  </joint>  
</robot>
