<?xml version="1.0" ?>

<robot name="autobot" xmlns:xacro="http://ros.org/wiki/xacro">

<xacro:include filename="$(find autobot_description)/urdf/bot.gazebo" />

<xacro:macro name="box_inertia" params="b_mass b_x b_y b_z">
        <mass value="${b_mass}"/>
        <inertia  ixx="${b_mass*(b_y*b_y+b_z*b_z)/12}" ixy = "0" ixz = "0"
                  iyy="${b_mass*(b_x*b_x+b_z*b_z)/12}" iyz = "0"
                  izz="${b_mass*(b_x*b_x+b_y*b_y)/12}"/>
</xacro:macro>


<xacro:macro name="cylinder_inertia" params="c_mass r l">
        <mass value="${c_mass}"/>
        <inertia  ixx="${c_mass*(3*r*r+l*l)/12}" ixy = "0" ixz = "0"
                  iyy="${c_mass*(3*r*r+l*l)/12}" iyz = "0"
                  izz="${c_mass*(r*r)/2}" />
</xacro:macro>

<link name="base_footprint" />

<link name="base_link" >
  <inertial>
    <origin xyz = "0 0 0" rpy = "0 0 0" />
    <xacro:box_inertia b_mass="17" b_x = "0.72" b_y = "0.40" b_z = "0.28" />
  </inertial>
  <visual>
	<origin xyz = "0 0 0" rpy = "0 0 0" />
        <geometry>
          <box size="0.72 0.40 0.28"/>
        </geometry>
        <material name="base_material">
          <color rgba="0 1 0 1"/>
        </material>
      </visual> 
      <collision>
        <origin xyz = "0 0 0" rpy = "0 0 0" />
        <geometry>
          <box size="0.72 0.40 0.28"/>
        </geometry>
      </collision>
</link>

<link name="left_wheel" >
 <origin xyz = "0 0 0" rpy = "0 0 0" />
  <inertial>
    <origin xyz = "0 0 0" rpy = "0 0 0" />
    <xacro:cylinder_inertia c_mass = "2" r = "0.08" l = "0.06" />
    </inertial>
  <visual>
    <origin xyz = "0 0 0" rpy = "0 0 0" />
    <geometry>
      <cylinder length="0.06" radius="0.08"/>
    </geometry>
    <material name="l_wheel">
      <color rgba="0 0 1 1"/>
    </material>
  </visual>
  <collision>
    <origin xyz = "0 0 0" rpy = "0 0 0" />
    <geometry>
      <cylinder length="0.06" radius="0.08"/>
    </geometry>
  </collision>
</link>

<link name="right_wheel" >
 <origin xyz = "0 0 0" rpy = "0 0 0" />
  <inertial>
    <origin xyz = "0 0 0" rpy = "0 0 0" />
    <xacro:cylinder_inertia c_mass = "2" r = "0.08" l = "0.06" />
    </inertial>
  <visual>
    <origin xyz = "0 0 0" rpy = "0 0 0" />
    <geometry>
      <cylinder length="0.06" radius="0.08"/>
    </geometry>
    <material name="r_wheel">
      <color rgba="0 0 1 1"/>
    </material>
  </visual>
  <collision>
    <origin xyz = "0 0 0" rpy = "0 0 0" />
    <geometry>
      <cylinder length="0.06" radius="0.08"/>
    </geometry>
  </collision>
</link>

<link name="laser" >
<origin xyz = "0 0 0" rpy = "0 0 0" />
<inertial>
  <mass value="0.09"/>
      <inertia ixx="4.275e-05" ixy="0" ixz="0" iyy="4.275e-05" iyz="0" izz="5.5125e-05"/>
</inertial>
<visual>
  <origin xyz = "0 0 0" rpy = "0 0 0" />
       <geometry>
        <cylinder length = "0.040" radius = "0.030" />
      </geometry>
      <material name="lidar_mat">
        <color rgba="1 0 0 1"/>
      </material>
    </visual>
    <collision>
      <origin xyz = "0 0 0" rpy = "0 0 0" />
      <geometry>
        <cylinder length = "0.040" radius = "0.030" />
      </geometry>
    </collision>
</link>

<link name="frontCastor_link">
  <collision>
    <origin xyz="0 0 0" rpy="0 0 0"/>
    <geometry>
      <mesh filename="package://autobot_description/meshes/castor_wheel.STL" scale= "0.001 0.001 0.001"/>
    </geometry>
  </collision>

  <visual>
    <origin xyz="0 0 0" rpy="0 0 0"/>
  <geometry>
    <mesh filename="package://autobot_description/meshes/castor_wheel.STL" scale="0.001 0.001 0.001"/>
    </geometry>
  </visual>

  <inertial>
    <mass value="0.30" />
    <origin xyz="0 0 0" rpy="0 0 0"/>
    <inertia ixx="0.0144" ixy="0" ixz="0" iyy="0.0144" iyz="0" izz="0.0144" />
  </inertial>
</link>

<link name="backCastor_link">
  <collision>
    <origin xyz="0 0 0" rpy="0 0 0"/>
    <geometry>
      <mesh filename="package://autobot_description/meshes/castor_wheel.STL" scale= "0.001 0.001 0.001"/>
    </geometry>
  </collision>

  <visual>
    <origin xyz="0 0 0" rpy="0 0 0"/>
  <geometry>
    <mesh filename="package://autobot_description/meshes/castor_wheel.STL" scale="0.001 0.001 0.001"/>
    </geometry>
  </visual>

  <inertial>
    <mass value="0.30" />
    <origin xyz="0 0 0" rpy="0 0 0"/>
    <inertia ixx="0.0144" ixy="0" ixz="0" iyy="0.0144" iyz="0" izz="0.0144" />
  </inertial>
</link>

<!-- IMU -->
  <link name="imu_link">
    <collision>
      <origin xyz="0 0 0" rpy="0 0 0"/>
      <geometry>
        <mesh filename="package://autobot_description/meshes/imu.STL" scale= "0.001 0.001 0.001"/>
      </geometry>
    </collision>

    <visual>
      <origin xyz="0 0 0" rpy="1.57 0 1.57"/>
    <geometry>
      <mesh filename="package://autobot_description/meshes/imu.STL" scale="0.001 0.001 0.001"/>
      </geometry>
    </visual>

    <inertial>
      <mass value="1e-5" />
      <origin xyz="0 0 0" rpy="0 0 0"/>
      <inertia ixx="0" ixy="0" ixz="0" iyy="0" iyz="0" izz="0" />
    </inertial>
  </link>

  <!-- Camera T265 link -->

    <link name="t265_link">
    <collision>
      <origin xyz="0 0 0" rpy="0 0 0"/>
      <geometry>
        <mesh filename="package://autobot_description/meshes/T265.STL" scale="0.001 0.001 0.001"/>
      </geometry>
    </collision>

    <visual>
      <origin xyz="0 0 0" rpy="0 0 0"/>
    <geometry>
      <mesh filename="package://autobot_description/meshes/T265.STL" scale="0.001 0.001 0.001"/>
      </geometry>
    </visual>

    <inertial>
      <mass value="1e-5" />
      <origin xyz="0 0 0" rpy="0 0 0"/>
      <inertia ixx="0" ixy="0" ixz="0" iyy="0" iyz="0" izz="0" />
    </inertial>
  </link>

  <!-- Camera D435i link -->

    <link name="camera_link">
    <collision>
      <origin xyz="0 0 0" rpy="0 0 0"/>
      <geometry>
        <mesh filename="package://autobot_description/meshes/D435i.STL" scale="0.001 0.001 0.001"/>
      </geometry>
    </collision>

    <visual>
      <origin xyz="0 0 0" rpy="1.57 0 1.57"/>
    <geometry>
      <mesh filename="package://autobot_description/meshes/D435i.STL" scale="0.001 0.001 0.001"/>
      </geometry>
    </visual>

    <inertial>
      <mass value="1e-5" />
      <origin xyz="0 0 0" rpy="0 0 0"/>
      <inertia ixx="0" ixy="0" ixz="0" iyy="0" iyz="0" izz="0" />
    </inertial>
  </link>
<link name="camera_depth" />
<joint name="footprint_link_joint" type="fixed" >
    <parent link = "base_footprint"/>
    <child link = "base_link" />
    <origin xyz = "0 0 0.20" rpy = "0 0 0" />
</joint>

<joint name="baselink_leftwheel" type="continuous" >
  <axis xyz = "0 0 1" />
  <parent link = "base_link"/>
  <child link = "left_wheel" />
  <origin xyz = "0 0.23 -0.12" rpy = "1.57 0 3.14 " />
</joint>

<joint name="baselink_rightwheel" type="continuous" >
  <axis xyz = "0 0 1" />
  <parent link = "base_link"/>
  <child link = "right_wheel" />
  <origin xyz = "0 -0.23 -0.12" rpy = "1.57 0 3.14" />
</joint>

<joint name="baselink_lidar" type="fixed" >
  <parent link = "base_link"/>
  <child link = "laser" />
  <origin xyz = "0.18 0 0.16" rpy = "3.14 3.14 0" />
</joint>

<joint name="imujoint" type="fixed">
    <origin xyz="0.216 0 0.216" rpy="3.14 3.14 0" />
    <parent link="base_link" />
    <child link="imu_link" />
    <axis xyz="0 0 1" />
</joint>

<joint name="frontCastor_joint" type="fixed" >
    <origin xyz = "0.30 0 -0.14" rpy = "0 0 0" />
    <parent link="base_link" />
    <child link ="frontCastor_link" />
</joint>

<joint name="backCastor_joint" type="fixed" >
  <origin xyz = "-0.30 0 -0.14" rpy = "0 0 0" />
  <parent link="base_link" />
  <child link ="backCastor_link" />
</joint>

<joint name="t265_joint" type="fixed" >
  <origin xyz = "0.425 0 -0.12" rpy = "1.57 0 -1.57" />
  <parent link="base_link" />
  <child link ="t265_link" />
</joint>

<joint name="d435_joint" type="fixed" >
  <origin xyz = "0.395 0 -0.065" rpy = "0 0 0" />
  <parent link="base_link" />
  <child link ="camera_link" />
</joint>

<joint name="depth_joint" type="fixed" >
  <origin xyz = "0.395 0 -0.065" rpy = "-1.57 0 -1.57" />
  <parent link="base_link" />
  <child link ="camera_depth" />
</joint>
</robot>
